<?xml version='1.0' encoding='utf-8'?>
<robot name="blueberry_plant">

	<!-- - - - - - --> 
	<!-- Base link -->
	<!-- - - - - - -->
	
	<link name="base_link">
		<inertial>
			<mass value="100000" />
			<inertia ixx="6333.33333" 
					 ixy="0.0" 
					 ixz="0.0" 
					 iyy="6333.33333" 
					 iyz="0.0" 
					 izz="12500.0" />
		</inertial>
		<visual>
			<origin xyz="0 0 0" 
					rpy="0 0 0" />
			<geometry>
				<cylinder length="0.05" 
						  radius="0.5" />
			</geometry>
			<material name="blue">
				<color rgba="0 0 1 1" />
			</material>
		</visual>
		<collision>
			<origin xyz="0 0 0" 
					rpy="0 0 0" />
			<geometry>
				<cylinder length="0.05" 
						  radius="0.5" />
			</geometry>
		</collision>
	</link>

	<!-- - - - - - - -->
	<!-- Revolute Joint -->
	<!-- - - - - - - -->
	
	<joint name="base_branch_joint" 
		   type="revolute">
		<parent link="base_link" />
		<child link="branch_link" />
		<axis xyz="0 1 0" />
		<origin xyz="0 0 0.05" 
				rpy="0 0 0" />
		<limit lower="-1.57" 
			   upper="1.57" 
			   effort="10" 
			   velocity="1.0" />
	</joint>

	<!-- - - - - - - -->
	<!-- First actual branch -->
	<!-- - - - - - - -->
	
	<link name="branch_link">
		<inertial>
			<mass value="0.05052" />
			<inertia ixx="0.01051" 
					 ixy="0.0" 
					 ixz="0.0" 
					 iyy="0.01051" 
					 iyz="0.0" 
					 izz="9.338e-07" />
		</inertial>
		<visual>
			<origin xyz="0 0 0.025" 
					rpy="0 0 0" />
			<geometry>
				<cylinder length="0.79" 
						  radius="0.00608" />
			</geometry>
			<material name="green">
				<color rgba="0 1 0 1" />
			</material>
		</visual>
		<collision>
			<origin xyz="0 0 0.025" 
					rpy="0 0 0" />
			<geometry>
				<cylinder length="0.79" 
						  radius="0.00608" />
			</geometry>
		</collision>
	</link>
</robot>